namespace NBug.Examples.WinForms
{
	using System;
	using System.Threading.Tasks;
	using System.Windows.Forms;

	public partial class MainForm : Form
	{
		public MainForm()
		{
			InitializeComponent();
            NBug.Settings.CustomUIEvent += Settings_CustomUIEvent;

			this.crashTypeComboBox.SelectedIndex = 0;
		}

        void Settings_CustomUIEvent(object sender, CustomUIEventArgs e)
        {
            var Form = new Normal();
            e.Result = Form.ShowDialog(e.Report);
        }

		private unsafe void CrashButton_Click(object sender, EventArgs e)
		{
			switch (this.crashTypeComboBox.Text)
			{
				case "UI Thread: System.Exception":
					throw new Exception("Selected exception: '" + this.crashTypeComboBox.Text + "' was thrown.");
				case "UI Thread: System.ArgumentException":
					throw new ArgumentException("Selected exception: '" + this.crashTypeComboBox.Text + "' was thrown.", "MyInvalidParameter", new Exception("Test inner exception for argument exception."));
				case "Background Thread (Task): System.Exception":
					Task.Factory.StartNew(() => { throw new Exception(); });
					// Below code makes sure that exception is thrown as only after finalization, the aggregateexception is thrown.
					// As a side affect, unlike the normal behavior, the applicaiton will note continue its execution but will shut
					// down just like any main thread exceptions, even if there is no handle to UnobservedTaskException!
					// So remove below 3 lines to observe the normal continuation behavior.
					System.Threading.Thread.Sleep(200);
					GC.Collect();
					GC.WaitForPendingFinalizers();
					break;
				case "Process Corrupted State Exception: Access Violation":
					this.AccessViolation();
					break;
			}
		}

		private unsafe void AccessViolation()
		{
			byte b = *(byte*)(8762765876);
		}

		private void CloseButton_Click(object sender, EventArgs e)
		{
			this.Close();
		}
	}
}
